Workbook

Sheet Monthly Material Planning
J2: Monthly Production Forecast (+2days Buffer) | AA2: Monthly Actual Production
J3: KCB2 | K3: KCA5 (& Kits) | L3: KWB3.1 (& Kits) | M3: KCA3.5 | N3: KAB3 (& Kits) | AA3: KCB2 | AB3: KCA5 (& Kits) | AC3: KWB3.1 (& Kits) | AD3: KCA3.5 | AE3: KAB3 (& Kits)
B6: Material Part # | C6: Raw Material Description | D6: Sheet Weight | E6: Material Requirement/ Product | J6: Projected Monthly Material Requirement (Kgs) | P6: Opening Material Balance (Kg) | Q6: Net Material Requirement (Kg) | R6: Net Material Requirement (Pcs) | S6: Projected Scrap | U6: Expected Material Consumption based on Actual Products Made | AA6: Actual Monthly Material Consumption (Kg) | AG6: Actual Scrap | AI6: Material Use Variance [Expected vs Actual] | AJ6: Reason (s) for Variance | AK6: Closing Material Balances (Kg)
E7: KCB2 | F7: KCA5 | G7: KWB3.1 | H7: KCA3.5 | I7: KAB3 | J7: KCB2 | K7: KCA5 | L7: KWB3.1 | M7: KCA3.5 | N7: KAB3 | O7: All Products | S7: % | T7: Kgs | U7: KCB2 | V7: KCA5 | W7: KWB3.1 | X7: KCA3.5 | Y7: KAB3 | Z7: All Products | AA7: KCB2 | AB7: KCA5 | AC7: KWB3.1 | AD7: KCA3.5 | AE7: KAB3 | AF7: All Products | AG7: Kgs | AH7: %
B8: 11279 | C8: AZ150 0.6mm Galvalume Coated Carbon Steel; Sheet; 1219mm W × 2300mm L | D8: ='Master Data'!J3 -> 12.8 | E8: ='Cumulative Material Use'!$E$3 -> 0.9643 | F8: ='Cumulative Material Use'!$E$11 -> 0.2414 | G8: ='Cumulative Material Use'!$E$24 -> 0.5068 | H8: ='Cumulative Material Use'!$E$34 -> 0.969 | J8: =E8*$J$4 -> 0 | K8: =F8*$K$4 -> 0 | L8: =G8*$L$4 -> 0 | M8: =H8*$M$4 -> 0 | N8: =I8*$N$4 -> 0 | O8: =SUM(J8:N8) -> 0 | Q8: =O8-P8 -> 0 | R8: =Q8/D8 -> 0 | U8: =E8*$AA$4 -> 0 | V8: =F8*$AB$4 -> 0 | W8: =G8*$AC$4 -> 0 | X8: =H8*$AD$4 -> 0 | Y8: =I8*$AE$4 -> 0 | Z8: =SUM(U8:Y8) -> 0 | AF8: =SUM(AA8:AE8) -> 0
B9: 10072B | C9: AZ100 0.7 Galvalume Sheet; 1219mm W x 2438mm L | D9: ='Master Data'!J6 -> 17 | E9: ='Cumulative Material Use'!$E$4 -> 0.2646 | H9: ='Cumulative Material Use'!$E$38 -> 0.0636 | J9: =E9*$J$4 -> 0 | K9: =F9*$K$4 -> 0 | L9: =G9*$L$4 -> 0 | M9: =H9*$M$4 -> 0 | N9: =I9*$N$4 -> 0 | O9: =SUM(J9:N9) -> 0 | Q9: =O9-P9 -> 0 | R9: =Q9/D9 -> 0 | U9: =E9*$AA$4 -> 0 | V9: =F9*$AB$4 -> 0 | W9: =G9*$AC$4 -> 0 | X9: =H9*$AD$4 -> 0 | Y9: =I9*$AE$4 -> 0 | Z9: =SUM(U9:Y9) -> 0 | AF9: =SUM(AA9:AE9) -> 0
B10: 10154 | C10: SS439; Sheet; With PVC Coating; 0.6mm thk x 1219mm W × 2438mm L | D10: ='Master Data'!J7 -> 13.5 | E10: ='Cumulative Material Use'!$E$5 -> 0.054 | F10: ='Cumulative Material Use'!$E$13 -> 0.1646 | G10: ='Cumulative Material Use'!$E$20 -> 0.68471 | H10: ='Cumulative Material Use'!$E$35 -> 0.1899 | I10: ='Cumulative Material Use'!$E$31 -> 0.0576 | J10: =E10*$J$4 -> 0 | K10: =F10*$K$4 -> 0 | L10: =G10*$L$4 -> 0 | M10: =H10*$M$4 -> 0 | N10: =I10*$N$4 -> 0 | O10: =SUM(J10:N10) -> 0 | Q10: =O10-P10 -> 0 | R10: =Q10/D10 -> 0 | U10: =E10*$AA$4 -> 0 | V10: =F10*$AB$4 -> 0 | W10: =G10*$AC$4 -> 0 | X10: =H10*$AD$4 -> 0 | Y10: =I10*$AE$4 -> 0 | Z10: =SUM(U10:Y10) -> 0 | AF10: =SUM(AA10:AE10) -> 0
B11: 10155 | C11: SS439; Sheet; With PVC Coating; 0.8mm thk × 1219mm W x 2438mm L | D11: ='Master Data'!J9 -> 18.1 | E11: ='Cumulative Material Use'!$E$6 -> 0.66821 | F11: ='Cumulative Material Use'!$E$15 -> 0.50701 | G11: ='Cumulative Material Use'!$E$26 -> 0.0789 | H11: ='Cumulative Material Use'!$E$36 -> 0.4622 | J11: =E11*$J$4 -> 0 | K11: =F11*$K$4 -> 0 | L11: =G11*$L$4 -> 0 | M11: =H11*$M$4 -> 0 | N11: =I11*$N$4 -> 0 | O11: =SUM(J11:N11) -> 0 | Q11: =O11-P11 -> 0 | R11: =Q11/D11 -> 0 | U11: =E11*$AA$4 -> 0 | V11: =F11*$AB$4 -> 0 | W11: =G11*$AC$4 -> 0 | X11: =H11*$AD$4 -> 0 | Y11: =I11*$AE$4 -> 0 | Z11: =SUM(U11:Y11) -> 0 | AF11: =SUM(AA11:AE11) -> 0
B12: 11332 | C12: SS321; Sheet; 1.5mm thk × 1000mm W x 2660mm L | D12: ='Master Data'!J11 -> 31.7 | E12: ='Cumulative Material Use'!$E$7 -> 0.5167 | F12: ='Cumulative Material Use'!$E$16 -> 0.5267 | H12: ='Cumulative Material Use'!$E$42 -> 0.5852 | J12: =E12*$J$4 -> 0 | K12: =F12*$K$4 -> 0 | L12: =G12*$L$4 -> 0 | M12: =H12*$M$4 -> 0 | N12: =I12*$N$4 -> 0 | O12: =SUM(J12:N12) -> 0 | Q12: =O12-P12 -> 0 | R12: =Q12/D12 -> 0 | U12: =E12*$AA$4 -> 0 | V12: =F12*$AB$4 -> 0 | W12: =G12*$AC$4 -> 0 | X12: =H12*$AD$4 -> 0 | Y12: =I12*$AE$4 -> 0 | Z12: =SUM(U12:Y12) -> 0 | AF12: =SUM(AA12:AE12) -> 0
B13: 10070B | C13: 1008 0.6 CRCA Carbon Steel; Sheet; 1219mm W × 2675mm L | D13: ='Master Data'!J18 -> 15.6 | E13: ='Cumulative Material Use'!$E$8 -> 1.08 | H13: ='Cumulative Material Use'!$E$39 -> 0.8213 | J13: =E13*$J$4 -> 0 | K13: =F13*$K$4 -> 0 | L13: =G13*$L$4 -> 0 | M13: =H13*$M$4 -> 0 | N13: =I13*$N$4 -> 0 | O13: =SUM(J13:N13) -> 0 | Q13: =O13-P13 -> 0 | R13: =Q13/D13 -> 0 | U13: =E13*$AA$4 -> 0 | V13: =F13*$AB$4 -> 0 | W13: =G13*$AC$4 -> 0 | X13: =H13*$AD$4 -> 0 | Y13: =I13*$AE$4 -> 0 | Z13: =SUM(U13:Y13) -> 0 | AF13: =SUM(AA13:AE13) -> 0
B14: 11090 | C14: SS201; Sheet; With PVC Coating; 0.5mm thk x 1219.2mm W × 2675mm L; Hairline | D14: ='Master Data'!J19 -> 12.7 | E14: ='Cumulative Material Use'!$E$9 -> 0.0356 | F14: ='Cumulative Material Use'!$E$14 -> 0.07214 | G14: ='Cumulative Material Use'!$E$23 -> 0.01154 | H14: ='Cumulative Material Use'!$E$40 -> 0.01154 | I14: ='Cumulative Material Use'!$E$30 -> 0.40645 | J14: =E14*$J$4 -> 0 | K14: =F14*$K$4 -> 0 | L14: =G14*$L$4 -> 0 | M14: =H14*$M$4 -> 0 | N14: =I14*$N$4 -> 0 | O14: =SUM(J14:N14) -> 0 | Q14: =O14-P14 -> 0 | R14: =Q14/D14 -> 0 | U14: =E14*$AA$4 -> 0 | V14: =F14*$AB$4 -> 0 | W14: =G14*$AC$4 -> 0 | X14: =H14*$AD$4 -> 0 | Y14: =I14*$AE$4 -> 0 | Z14: =SUM(U14:Y14) -> 0 | AF14: =SUM(AA14:AE14) -> 0
B15: 10073 | C15: Carbon Steel Tubing; 10mm OD x 1mm wall x 3m L | E15: ='Cumulative Material Use'!$E$10 -> 0.11 | H15: ='Cumulative Material Use'!$E$41 -> 0.11 | J15: =E15*$J$4 -> 0 | K15: =F15*$K$4 -> 0 | L15: =G15*$L$4 -> 0 | M15: =H15*$M$4 -> 0 | N15: =I15*$N$4 -> 0 | O15: =SUM(J15:N15) -> 0 | Q15: =O15-P15 -> 0 | R15: =Q15/D15 -> #DIV/0! | U15: =E15*$AA$4 -> 0 | V15: =F15*$AB$4 -> 0 | W15: =G15*$AC$4 -> 0 | X15: =H15*$AD$4 -> 0 | Y15: =I15*$AE$4 -> 0 | Z15: =SUM(U15:Y15) -> 0 | AF15: =SUM(AA15:AE15) -> 0
B16: 10970 | C16: AZ150 0.6mm Galvalume Coated Steel Sheet; 1219mm w x 2500mm L (DX53D) | D16: ='Master Data'!J33 -> 13.6 | F16: ='Cumulative Material Use'!$E$12 -> 0.4103 | J16: =E16*$J$4 -> 0 | K16: =F16*$K$4 -> 0 | L16: =G16*$L$4 -> 0 | M16: =H16*$M$4 -> 0 | N16: =I16*$N$4 -> 0 | O16: =SUM(J16:N16) -> 0 | Q16: =O16-P16 -> 0 | R16: =Q16/D16 -> 0 | U16: =E16*$AA$4 -> 0 | V16: =F16*$AB$4 -> 0 | W16: =G16*$AC$4 -> 0 | X16: =H16*$AD$4 -> 0 | Y16: =I16*$AE$4 -> 0 | Z16: =SUM(U16:Y16) -> 0 | AF16: =SUM(AA16:AE16) -> 0
B17: 11213B | C17: SS201; Sheet; With PVC Coating; 0.4mm thk x 1219mm W × 2438mm L; Hairline | D17: ='Master Data'!J35 -> 10 | F17: ='Cumulative Material Use'!$E$17 -> 0.55556 | J17: =E17*$J$4 -> 0 | K17: =F17*$K$4 -> 0 | L17: =G17*$L$4 -> 0 | M17: =H17*$M$4 -> 0 | N17: =I17*$N$4 -> 0 | O17: =SUM(J17:N17) -> 0 | Q17: =O17-P17 -> 0 | R17: =Q17/D17 -> 0 | U17: =E17*$AA$4 -> 0 | V17: =F17*$AB$4 -> 0 | W17: =G17*$AC$4 -> 0 | X17: =H17*$AD$4 -> 0 | Y17: =I17*$AE$4 -> 0 | Z17: =SUM(U17:Y17) -> 0 | AF17: =SUM(AA17:AE17) -> 0
B18: 11442 | C18: SS201; Sheet; Without PVC Coating; 0.8mm thk x 1219mm W × 2438mm L; BA Finish | D18: ='Master Data'!J36 -> 17.7 | F18: ='Cumulative Material Use'!$E$18 -> 0.07434 | G18: ='Cumulative Material Use'!$E$21 -> 0.07434 | J18: =E18*$J$4 -> 0 | K18: =F18*$K$4 -> 0 | L18: =G18*$L$4 -> 0 | M18: =H18*$M$4 -> 0 | N18: =I18*$N$4 -> 0 | O18: =SUM(J18:N18) -> 0 | Q18: =O18-P18 -> 0 | R18: =Q18/D18 -> 0 | U18: =E18*$AA$4 -> 0 | V18: =F18*$AB$4 -> 0 | W18: =G18*$AC$4 -> 0 | X18: =H18*$AD$4 -> 0 | Y18: =I18*$AE$4 -> 0 | Z18: =SUM(U18:Y18) -> 0 | AF18: =SUM(AA18:AE18) -> 0
B19: 11515 | C19: SS201; Sheet; With PVC Coating; 0.4mm thk x 1219mm × 2190mm L; Hairline | D19: ='Master Data'!J38 -> 9.16 | G19: ='Cumulative Material Use'!$E$19 -> 0.71703 | J19: =E19*$J$4 -> 0 | K19: =F19*$K$4 -> 0 | L19: =G19*$L$4 -> 0 | M19: =H19*$M$4 -> 0 | N19: =I19*$N$4 -> 0 | O19: =SUM(J19:N19) -> 0 | Q19: =O19-P19 -> 0 | R19: =Q19/D19 -> 0 | U19: =E19*$AA$4 -> 0 | V19: =F19*$AB$4 -> 0 | W19: =G19*$AC$4 -> 0 | X19: =H19*$AD$4 -> 0 | Y19: =I19*$AE$4 -> 0 | Z19: =SUM(U19:Y19) -> 0 | AF19: =SUM(AA19:AE19) -> 0
B20: 10296A | C20: AZ100 0.2 Galvalume Sheet; 975mm W x 2438mm L | D20: ='Master Data'!J41 -> 3.55 | G20: ='Cumulative Material Use'!$E$22 -> 0.1961 | J20: =E20*$J$4 -> 0 | K20: =F20*$K$4 -> 0 | L20: =G20*$L$4 -> 0 | M20: =H20*$M$4 -> 0 | N20: =I20*$N$4 -> 0 | O20: =SUM(J20:N20) -> 0 | Q20: =O20-P20 -> 0 | R20: =Q20/D20 -> 0 | U20: =E20*$AA$4 -> 0 | V20: =F20*$AB$4 -> 0 | W20: =G20*$AC$4 -> 0 | X20: =H20*$AD$4 -> 0 | Y20: =I20*$AE$4 -> 0 | Z20: =SUM(U20:Y20) -> 0 | AF20: =SUM(AA20:AE20) -> 0
B21: 11040B | C21: SS304; Sheet; 1.2mm thk × 1219.2mm W × 2620mm L | D21: ='Master Data'!J48 -> 29.8 | G21: ='Cumulative Material Use'!$E$25 -> 0.4495 | I21: ='Cumulative Material Use'!$E$32 -> 0.0266 | J21: =E21*$J$4 -> 0 | K21: =F21*$K$4 -> 0 | L21: =G21*$L$4 -> 0 | M21: =H21*$M$4 -> 0 | N21: =I21*$N$4 -> 0 | O21: =SUM(J21:N21) -> 0 | Q21: =O21-P21 -> 0 | R21: =Q21/D21 -> 0 | U21: =E21*$AA$4 -> 0 | V21: =F21*$AB$4 -> 0 | W21: =G21*$AC$4 -> 0 | X21: =H21*$AD$4 -> 0 | Y21: =I21*$AE$4 -> 0 | Z21: =SUM(U21:Y21) -> 0 | AF21: =SUM(AA21:AE21) -> 0
B22: 11226 | C22: SS439; Sheet; 1.2mm thk × 1219mm W × 2438mm L | D22: ='Master Data'!J50 -> 27.3 | G22: ='Cumulative Material Use'!$E$27 -> 0.47901 | J22: =E22*$J$4 -> 0 | K22: =F22*$K$4 -> 0 | L22: =G22*$L$4 -> 0 | M22: =H22*$M$4 -> 0 | N22: =I22*$N$4 -> 0 | O22: =SUM(J22:N22) -> 0 | Q22: =O22-P22 -> 0 | R22: =Q22/D22 -> 0 | U22: =E22*$AA$4 -> 0 | V22: =F22*$AB$4 -> 0 | W22: =G22*$AC$4 -> 0 | X22: =H22*$AD$4 -> 0 | Y22: =I22*$AE$4 -> 0 | Z22: =SUM(U22:Y22) -> 0 | AF22: =SUM(AA22:AE22) -> 0
B23: 10074 | C23: SS304; Sheet; 0.8mm x 1219mm W × 2438mm L | D23: ='Master Data'!J75 -> 19 | H23: ='Cumulative Material Use'!$E$37 -> 0.00792 | M23: =H23*$M$4 -> 0 | R23: =Q23/D23 -> 0 | X23: =H23*$AD$4 -> 0
B24: 11291 | C24: SS201; Wire; 4mm dia x 2400mm L | D24: ='Master Data'!J57 -> 0.2379 | G24: ='Cumulative Material Use'!$E$28 -> 0.0804 | J24: =E24*$J$4 -> 0 | K24: =F24*$K$4 -> 0 | L24: =G24*$L$4 -> 0 | M24: =H24*$M$4 -> 0 | N24: =I24*$N$4 -> 0 | O24: =SUM(J24:N24) -> 0 | Q24: =O24-P24 -> 0 | R24: =Q24/D24 -> 0 | U24: =E24*$AA$4 -> 0 | V24: =F24*$AB$4 -> 0 | W24: =G24*$AC$4 -> 0 | X24: =H24*$AD$4 -> 0 | Y24: =I24*$AE$4 -> 0 | Z24: =SUM(U24:Y24) -> 0 | AF24: =SUM(AA24:AE24) -> 0
B25: 11290 | C25: SS201; Wire; 3mm dia x 2400mm L | D25: ='Master Data'!J58 -> 0.1308 | G25: ='Cumulative Material Use'!$E$29 -> 0.0555 | J25: =E25*$J$4 -> 0 | K25: =F25*$K$4 -> 0 | L25: =G25*$L$4 -> 0 | M25: =H25*$M$4 -> 0 | N25: =I25*$N$4 -> 0 | O25: =SUM(J25:N25) -> 0 | Q25: =O25-P25 -> 0 | R25: =Q25/D25 -> 0 | U25: =E25*$AA$4 -> 0 | V25: =F25*$AB$4 -> 0 | W25: =G25*$AC$4 -> 0 | X25: =H25*$AD$4 -> 0 | Y25: =I25*$AE$4 -> 0 | Z25: =SUM(U25:Y25) -> 0 | AF25: =SUM(AA25:AE25) -> 0

Sheet Weekly Material Planning
K2: Weekly Production Forecast | AD2: Weekly Actual Production
K3: KCB2 | L3: KCA5 (& Kits) | M3: KWB3.1 (& Kits) | N3: KCA3.5 | O3: KAB3 (& Kits) | AD3: KCB2 | AE3: KCA5 (& Kits) | AF3: KWB3.1 (& Kits) | AG3: KCA3.5 | AH3: KAB3 (& Kits)
I4: Week2 | J4: Week2 | K4: 10000 | L4: =10500+20700 -> 31200 | N4: 10500 | AC4: Week2 | AD4: 3000
I5: Week3 | J5: Week3 | AC5: Week3
I6: Week4 | J6: Week4 | AC6: Week4
I7: Week5 | J7: Week5 | AC7: Week5
B9: Week2
B10: Material Part # | C10: Raw Material Description | D10: Sheet Weight | E10: Material Requirement/ Product | K10: Projected Weekly Material Requirement (Kgs) | Q10: Opening Material Balance (Kg) | R10: Net Material Requirement (Kg) | S10: Net Material Requirement (Pcs) | T10: Material Physically Received (Kg) | U10: Material Transferred to Prod. In NAV (Kg) | V10: Projected Scrap | X10: Expected Material Consumption based on Actual Products Made(Kgs) | AD10: Actual Weekly Material Consumption (Kgs) | AJ10: Actual Scrap | AL10: Material Use Variance [Expected vs Actual] | AM10: Any change in Material within the Week on the Final Product (TPD/ ECN)? | AN10: Any other reason for Variance? | AO10: Closing Material Balances (Kg)
E11: KCB2 | F11: KCA5 | G11: KWB3.1 | H11: KCA3.5 | I11: KAB3 | K11: KCB2 | L11: KCA5 | M11: KWB3.1 | N11: KCA3.5 | O11: KAB3 | P11: All Products | V11: % | W11: Kgs | X11: KCB2 | Y11: KCA5 | Z11: KWB3.1 | AA11: KCA3.5 | AB11: KAB3 | AC11: All Products | AD11: KCB2 | AE11: KCA5 | AF11: KWB3.1 | AG11: KCA3.5 | AH11: KAB3 | AI11: All Products | AJ11: Kgs | AK11: %
B12: 11279 | C12: AZ150 0.6mm Galvalume Coated Carbon Steel; Sheet; 1219mm W × 2300mm L | D12: ='Monthly Material Planning'!$D$8 -> 12.8 | E12: ='Cumulative Material Use'!$E$3 -> 0.9643 | F12: ='Cumulative Material Use'!$E$11 -> 0.2414 | G12: ='Cumulative Material Use'!$E$24 -> 0.5068 | H12: ='Cumulative Material Use'!$E$34 -> 0.969 | K12: =E12*$K$4 -> 9643 | L12: =F12*$L$4 -> 7531.68 | M12: =G12*$M$4 -> 0 | N12: =H12*$N$4 -> 10174.5 | O12: =I12*$O$4 -> 0 | P12: =SUM(K12:O12) -> 27349.18 | Q12: 29642.89 | R12: =P12-Q12 -> -2293.71 | S12: =R12/D12 -> -179.19609 | X12: =E12*$AD$4 -> 2892.9 | Y12: =F12*$AE$4 -> 0 | Z12: =G12*$AF$4 -> 0 | AA12: =H12*$AG$4 -> 0 | AB12: =I12*$AH$4 -> 0 | AC12: =SUM(X12:AB12) -> 2892.9 | AI12: =SUM(AD12:AH12) -> 0
B13: 10072B | C13: AZ100 0.7 Galvalume Sheet; 1219mm W x 2438mm L | D13: ='Monthly Material Planning'!$D$9 -> 17 | E13: ='Cumulative Material Use'!$E$4 -> 0.2646 | H13: ='Cumulative Material Use'!$E$38 -> 0.0636 | K13: =E13*$K$4 -> 2646 | L13: =F13*$L$4 -> 0 | M13: =G13*$M$4 -> 0 | N13: =H13*$N$4 -> 667.8 | O13: =I13*$O$4 -> 0 | P13: =SUM(K13:O13) -> 3313.8 | Q13: 8985.75 | R13: =P13-Q13 -> -5671.95 | S13: =R13/D13 -> -333.64412 | X13: =E13*$AD$4 -> 793.8 | Y13: =F13*$AE$4 -> 0 | Z13: =G13*$AF$4 -> 0 | AA13: =H13*$AG$4 -> 0 | AB13: =I13*$AH$4 -> 0 | AC13: =SUM(X13:AB13) -> 793.8 | AI13: =SUM(AD13:AH13) -> 0
B14: 10154 | C14: SS439; Sheet; With PVC Coating; 0.6mm thk x 1219mm W × 2438mm L | D14: ='Monthly Material Planning'!$D$10 -> 13.5 | E14: ='Cumulative Material Use'!$E$5 -> 0.054 | F14: ='Cumulative Material Use'!$E$13 -> 0.1646 | G14: ='Cumulative Material Use'!$E$20 -> 0.68471 | H14: ='Cumulative Material Use'!$E$35 -> 0.1899 | I14: ='Cumulative Material Use'!$E$31 -> 0.0576 | K14: =E14*$K$4 -> 540 | L14: =F14*$L$4 -> 5135.52 | M14: =G14*$M$4 -> 0 | N14: =H14*$N$4 -> 1993.95 | O14: =I14*$O$4 -> 0 | P14: =SUM(K14:O14) -> 7669.47 | Q14: 20767.93 | R14: =P14-Q14 -> -13098.46 | S14: =R14/D14 -> -970.2563 | X14: =E14*$AD$4 -> 162 | Y14: =F14*$AE$4 -> 0 | Z14: =G14*$AF$4 -> 0 | AA14: =H14*$AG$4 -> 0 | AB14: =I14*$AH$4 -> 0 | AC14: =SUM(X14:AB14) -> 162 | AI14: =SUM(AD14:AH14) -> 0
B15: 10155 | C15: SS439; Sheet; With PVC Coating; 0.8mm thk × 1219mm W x 2438mm L | D15: ='Monthly Material Planning'!$D$11 -> 18.1 | E15: ='Cumulative Material Use'!$E$6 -> 0.66821 | F15: ='Cumulative Material Use'!$E$15 -> 0.50701 | G15: ='Cumulative Material Use'!$E$26 -> 0.0789 | H15: ='Cumulative Material Use'!$E$36 -> 0.4622 | K15: =E15*$K$4 -> 6682.1 | L15: =F15*$L$4 -> 15818.712 | M15: =G15*$M$4 -> 0 | N15: =H15*$N$4 -> 4853.1 | O15: =I15*$O$4 -> 0 | P15: =SUM(K15:O15) -> 27353.912 | Q15: 31441.71 | R15: =P15-Q15 -> -4087.798 | S15: =R15/D15 -> -225.84519 | X15: =E15*$AD$4 -> 2004.63 | Y15: =F15*$AE$4 -> 0 | Z15: =G15*$AF$4 -> 0 | AA15: =H15*$AG$4 -> 0 | AB15: =I15*$AH$4 -> 0 | AC15: =SUM(X15:AB15) -> 2004.63 | AI15: =SUM(AD15:AH15) -> 0
B16: 11332 | C16: SS321; Sheet; 1.5mm thk × 1000mm W x 2660mm L | D16: ='Monthly Material Planning'!$D$12 -> 31.7 | E16: ='Cumulative Material Use'!$E$7 -> 0.5167 | F16: ='Cumulative Material Use'!$E$16 -> 0.5267 | H16: ='Cumulative Material Use'!$E$42 -> 0.5852 | K16: =E16*$K$4 -> 5167 | L16: =F16*$L$4 -> 16433.04 | M16: =G16*$M$4 -> 0 | N16: =H16*$N$4 -> 6144.6 | O16: =I16*$O$4 -> 0 | P16: =SUM(K16:O16) -> 27744.64 | Q16: 20254.3 | R16: =P16-Q16 -> 7490.34 | S16: =R16/D16 -> 236.28833 | X16: =E16*$AD$4 -> 1550.1 | Y16: =F16*$AE$4 -> 0 | Z16: =G16*$AF$4 -> 0 | AA16: =H16*$AG$4 -> 0 | AB16: =I16*$AH$4 -> 0 | AC16: =SUM(X16:AB16) -> 1550.1 | AI16: =SUM(AD16:AH16) -> 0
B17: 10070B | C17: 1008 0.6 CRCA Carbon Steel; Sheet; 1219mm W × 2675mm L | D17: ='Monthly Material Planning'!$D$13 -> 15.6 | E17: ='Cumulative Material Use'!$E$8 -> 1.08 | H17: ='Cumulative Material Use'!$E$39 -> 0.8213 | K17: =E17*$K$4 -> 10800 | L17: =F17*$L$4 -> 0 | M17: =G17*$M$4 -> 0 | N17: =H17*$N$4 -> 8623.65 | O17: =I17*$O$4 -> 0 | P17: =SUM(K17:O17) -> 19423.65 | Q17: 12409.07 | R17: =P17-Q17 -> 7014.58 | S17: =R17/D17 -> 449.65256 | X17: =E17*$AD$4 -> 3240 | Y17: =F17*$AE$4 -> 0 | Z17: =G17*$AF$4 -> 0 | AA17: =H17*$AG$4 -> 0 | AB17: =I17*$AH$4 -> 0 | AC17: =SUM(X17:AB17) -> 3240 | AI17: =SUM(AD17:AH17) -> 0
B18: 11090 | C18: SS201; Sheet; With PVC Coating; 0.5mm thk x 1219.2mm W × 2675mm L; Hairline | D18: ='Monthly Material Planning'!$D$14 -> 12.7 | E18: ='Cumulative Material Use'!$E$9 -> 0.0356 | F18: ='Cumulative Material Use'!$E$14 -> 0.07214 | G18: ='Cumulative Material Use'!$E$23 -> 0.01154 | H18: ='Cumulative Material Use'!$E$40 -> 0.01154 | I18: ='Cumulative Material Use'!$E$30 -> 0.40645 | K18: =E18*$K$4 -> 356 | L18: =F18*$L$4 -> 2250.768 | M18: =G18*$M$4 -> 0 | N18: =H18*$N$4 -> 121.17 | O18: =I18*$O$4 -> 0 | P18: =SUM(K18:O18) -> 2727.938 | Q18: 12358.52 | R18: =P18-Q18 -> -9630.582 | S18: =R18/D18 -> -758.31354 | X18: =E18*$AD$4 -> 106.8 | Y18: =F18*$AE$4 -> 0 | Z18: =G18*$AF$4 -> 0 | AA18: =H18*$AG$4 -> 0 | AB18: =I18*$AH$4 -> 0 | AC18: =SUM(X18:AB18) -> 106.8 | AI18: =SUM(AD18:AH18) -> 0
B19: 10073 | C19: Carbon Steel Tubing; 10mm OD x 1mm wall x 3m L | D19: ='Monthly Material Planning'!$D$15 -> 0 | E19: ='Cumulative Material Use'!$E$10 -> 0.11 | H19: ='Cumulative Material Use'!$E$41 -> 0.11 | K19: =E19*$K$4 -> 1100 | L19: =F19*$L$4 -> 0 | M19: =G19*$M$4 -> 0 | N19: =H19*$N$4 -> 1155 | O19: =I19*$O$4 -> 0 | P19: =SUM(K19:O19) -> 2255 | R19: =P19-Q19 -> 2255 | S19: =R19/D19 -> #DIV/0! | X19: =E19*$AD$4 -> 330 | Y19: =F19*$AE$4 -> 0 | Z19: =G19*$AF$4 -> 0 | AA19: =H19*$AG$4 -> 0 | AB19: =I19*$AH$4 -> 0 | AC19: =SUM(X19:AB19) -> 330 | AI19: =SUM(AD19:AH19) -> 0
B20: 10970 | C20: AZ150 0.6mm Galvalume Coated Steel Sheet; 1219mm w x 2500mm L (DX53D) | D20: ='Monthly Material Planning'!$D$16 -> 13.6 | F20: ='Cumulative Material Use'!$E$12 -> 0.4103 | K20: =E20*$K$4 -> 0 | L20: =F20*$L$4 -> 12801.36 | M20: =G20*$M$4 -> 0 | N20: =H20*$N$4 -> 0 | O20: =I20*$O$4 -> 0 | P20: =SUM(K20:O20) -> 12801.36 | Q20: 15172.558 | R20: =P20-Q20 -> -2371.198 | S20: =R20/D20 -> -174.35279 | X20: =E20*$AD$4 -> 0 | Y20: =F20*$AE$4 -> 0 | Z20: =G20*$AF$4 -> 0 | AA20: =H20*$AG$4 -> 0 | AB20: =I20*$AH$4 -> 0 | AC20: =SUM(X20:AB20) -> 0 | AI20: =SUM(AD20:AH20) -> 0
B21: 11213B | C21: SS201; Sheet; With PVC Coating; 0.4mm thk x 1219mm W × 2438mm L; Hairline | D21: ='Monthly Material Planning'!$D$17 -> 10 | F21: ='Cumulative Material Use'!$E$17 -> 0.55556 | K21: =E21*$K$4 -> 0 | L21: =F21*$L$4 -> 17333.472 | M21: =G21*$M$4 -> 0 | N21: =H21*$N$4 -> 0 | O21: =I21*$O$4 -> 0 | P21: =SUM(K21:O21) -> 17333.472 | Q21: 15912.22 | R21: =P21-Q21 -> 1421.252 | S21: =R21/D21 -> 142.1252 | X21: =E21*$AD$4 -> 0 | Y21: =F21*$AE$4 -> 0 | Z21: =G21*$AF$4 -> 0 | AA21: =H21*$AG$4 -> 0 | AB21: =I21*$AH$4 -> 0 | AC21: =SUM(X21:AB21) -> 0 | AI21: =SUM(AD21:AH21) -> 0
B22: 11442 | C22: SS201; Sheet; Without PVC Coating; 0.8mm thk x 1219mm W × 2438mm L; BA Finish | D22: ='Monthly Material Planning'!$D$18 -> 17.7 | F22: ='Cumulative Material Use'!$E$18 -> 0.07434 | G22: ='Cumulative Material Use'!$E$21 -> 0.07434 | K22: =E22*$K$4 -> 0 | L22: =F22*$L$4 -> 2319.408 | M22: =G22*$M$4 -> 0 | N22: =H22*$N$4 -> 0 | O22: =I22*$O$4 -> 0 | P22: =SUM(K22:O22) -> 2319.408 | Q22: 5442.19 | R22: =P22-Q22 -> -3122.782 | S22: =R22/D22 -> -176.42836 | X22: =E22*$AD$4 -> 0 | Y22: =F22*$AE$4 -> 0 | Z22: =G22*$AF$4 -> 0 | AA22: =H22*$AG$4 -> 0 | AB22: =I22*$AH$4 -> 0 | AC22: =SUM(X22:AB22) -> 0 | AI22: =SUM(AD22:AH22) -> 0
B23: 11515 | C23: SS201; Sheet; With PVC Coating; 0.4mm thk x 1219mm × 2190mm L; Hairline | D23: ='Monthly Material Planning'!$D$19 -> 9.16 | G23: ='Cumulative Material Use'!$E$19 -> 0.71703 | K23: =E23*$K$4 -> 0 | L23: =F23*$L$4 -> 0 | M23: =G23*$M$4 -> 0 | N23: =H23*$N$4 -> 0 | O23: =I23*$O$4 -> 0 | P23: =SUM(K23:O23) -> 0 | Q23: 1358 | R23: =P23-Q23 -> -1358 | S23: =R23/D23 -> -148.25328 | X23: =E23*$AD$4 -> 0 | Y23: =F23*$AE$4 -> 0 | Z23: =G23*$AF$4 -> 0 | AA23: =H23*$AG$4 -> 0 | AB23: =I23*$AH$4 -> 0 | AC23: =SUM(X23:AB23) -> 0 | AI23: =SUM(AD23:AH23) -> 0
B24: 10296A | C24: AZ100 0.2 Galvalume Sheet; 975mm W x 2438mm L | D24: ='Monthly Material Planning'!$D$20 -> 3.55 | G24: ='Cumulative Material Use'!$E$22 -> 0.1961 | K24: =E24*$K$4 -> 0 | L24: =F24*$L$4 -> 0 | M24: =G24*$M$4 -> 0 | N24: =H24*$N$4 -> 0 | O24: =I24*$O$4 -> 0 | P24: =SUM(K24:O24) -> 0 | Q24: 1623 | R24: =P24-Q24 -> -1623 | S24: =R24/D24 -> -457.1831 | X24: =E24*$AD$4 -> 0 | Y24: =F24*$AE$4 -> 0 | Z24: =G24*$AF$4 -> 0 | AA24: =H24*$AG$4 -> 0 | AB24: =I24*$AH$4 -> 0 | AC24: =SUM(X24:AB24) -> 0 | AI24: =SUM(AD24:AH24) -> 0
B25: 11040B | C25: SS304; Sheet; 1.2mm thk × 1219.2mm W × 2620mm L | D25: ='Monthly Material Planning'!$D$21 -> 29.8 | G25: ='Cumulative Material Use'!$E$25 -> 0.4495 | I25: ='Cumulative Material Use'!$E$32 -> 0.0266 | K25: =E25*$K$4 -> 0 | L25: =F25*$L$4 -> 0 | M25: =G25*$M$4 -> 0 | N25: =H25*$N$4 -> 0 | O25: =I25*$O$4 -> 0 | P25: =SUM(K25:O25) -> 0 | Q25: 1794 | R25: =P25-Q25 -> -1794 | S25: =R25/D25 -> -60.201342 | X25: =E25*$AD$4 -> 0 | Y25: =F25*$AE$4 -> 0 | Z25: =G25*$AF$4 -> 0 | AA25: =H25*$AG$4 -> 0 | AB25: =I25*$AH$4 -> 0 | AC25: =SUM(X25:AB25) -> 0 | AI25: =SUM(AD25:AH25) -> 0
B26: 11226 | C26: SS439; Sheet; 1.2mm thk × 1219mm W × 2438mm L | D26: ='Monthly Material Planning'!$D$22 -> 27.3 | G26: ='Cumulative Material Use'!$E$27 -> 0.47901 | K26: =E26*$K$4 -> 0 | L26: =F26*$L$4 -> 0 | M26: =G26*$M$4 -> 0 | N26: =H26*$N$4 -> 0 | O26: =I26*$O$4 -> 0 | P26: =SUM(K26:O26) -> 0 | Q26: 251.64 | R26: =P26-Q26 -> -251.64 | S26: =R26/D26 -> -9.2175824 | X26: =E26*$AD$4 -> 0 | Y26: =F26*$AE$4 -> 0 | Z26: =G26*$AF$4 -> 0 | AA26: =H26*$AG$4 -> 0 | AB26: =I26*$AH$4 -> 0 | AC26: =SUM(X26:AB26) -> 0 | AI26: =SUM(AD26:AH26) -> 0
B27: 10074 | C27: SS304; Sheet; 0.8mm x 1219mm W × 2438mm L | D27: ='Monthly Material Planning'!$D$23 -> 19 | H27: ='Cumulative Material Use'!$E$37 -> 0.00792 | N27: =H27*$N$4 -> 83.16 | Q27: 395.76 | S27: =R27/D27 -> 0 | AA27: =H27*$AG$4 -> 0
B28: 11291 | C28: SS201; Wire; 4mm dia x 2400mm L | D28: ='Monthly Material Planning'!$D$24 -> 0.2379 | G28: ='Cumulative Material Use'!$E$28 -> 0.0804 | K28: =E28*$K$4 -> 0 | L28: =F28*$L$4 -> 0 | M28: =G28*$M$4 -> 0 | N28: =H28*$N$4 -> 0 | O28: =I28*$O$4 -> 0 | P28: =SUM(K28:O28) -> 0 | R28: =P28-Q28 -> 0 | S28: =R28/D28 -> 0 | X28: =E28*$AD$4 -> 0 | Y28: =F28*$AE$4 -> 0 | Z28: =G28*$AF$4 -> 0 | AA28: =H28*$AG$4 -> 0 | AB28: =I28*$AH$4 -> 0 | AC28: =SUM(X28:AB28) -> 0 | AI28: =SUM(AD28:AH28) -> 0
B29: 11290 | C29: SS201; Wire; 3mm dia x 2400mm L | D29: ='Monthly Material Planning'!$D$25 -> 0.1308 | G29: ='Cumulative Material Use'!$E$29 -> 0.0555 | K29: =E29*$K$4 -> 0 | L29: =F29*$L$4 -> 0 | M29: =G29*$M$4 -> 0 | N29: =H29*$N$4 -> 0 | O29: =I29*$O$4 -> 0 | P29: =SUM(K29:O29) -> 0 | R29: =P29-Q29 -> 0 | S29: =R29/D29 -> 0 | X29: =E29*$AD$4 -> 0 | Y29: =F29*$AE$4 -> 0 | Z29: =G29*$AF$4 -> 0 | AA29: =H29*$AG$4 -> 0 | AB29: =I29*$AH$4 -> 0 | AC29: =SUM(X29:AB29) -> 0 | AI29: =SUM(AD29:AH29) -> 0
B31: Week3
B32: Material Part # | C32: Raw Material Description | D32: Sheet Weight | E32: Material Requirement/ Product | K32: Projected Weekly Material Requirement (Kgs) | Q32: Opening Material Balance (Kg) | R32: Net Material Requirement (Kg) | S32: Net Material Requirement (Pcs) | T32: Material Physically Received (Kg) | U32: Material Transferred to Prod. In NAV (Kg) | V32: Projected Scrap | X32: Expected Material Consumption based on Actual Products Made(Kgs) | AD32: Actual Monthly Material Consumption (Kgs) | AJ32: Actual Scrap | AL32: Material Use Variance [Expected vs Actual] | AM32: Any change in Material within the Week on the Final Product (TPD/ ECN)? | AN32: Any other reason for Variance? | AO32: Closing Material Balances (Kg)
E33: KCB2 | F33: KCA5 | G33: KWB3.1 | H33: KCA3.5 | I33: KAB3 | K33: KCB2 | L33: KCA5 | M33: KWB3.1 | N33: KCA3.5 | O33: KAB3 | P33: All Products | V33: % | W33: Kgs | X33: KCB2 | Y33: KCA5 | Z33: KWB3.1 | AA33: KCA3.5 | AB33: KAB3 | AC33: All Products | AD33: KCB2 | AE33: KCA5 | AF33: KWB3.1 | AG33: KCA3.5 | AH33: KAB3 | AI33: All Products | AJ33: Kgs | AK33: %
B34: 11279 | C34: AZ150 0.6mm Galvalume Coated Carbon Steel; Sheet; 1219mm W × 2300mm L | D34: ='Monthly Material Planning'!$D$8 -> 12.8 | E34: ='Cumulative Material Use'!$E$3 -> 0.9643 | F34: ='Cumulative Material Use'!$E$11 -> 0.2414 | G34: ='Cumulative Material Use'!$E$24 -> 0.5068 | H34: ='Cumulative Material Use'!$E$34 -> 0.969 | K34: =E34*$K$5 -> 0 | L34: =F34*$L$5 -> 0 | M34: =G34*$M$5 -> 0 | N34: =H34*$N$5 -> 0 | O34: =I34*$O$5 -> 0 | P34: =SUM(K34:O34) -> 0 | R34: =P34-Q34 -> 0 | S34: =R34/D34 -> 0 | X34: =E34*$AD$5 -> 0 | Y34: =F34*$AE$5 -> 0 | Z34: =G34*$AF$5 -> 0 | AA34: =H34*$AG$5 -> 0 | AB34: =I34*$AH$5 -> 0 | AC34: =SUM(X34:AB34) -> 0 | AI34: =SUM(AD34:AH34) -> 0
B35: 10072B | C35: AZ100 0.7 Galvalume Sheet; 1219mm W x 2438mm L | D35: ='Monthly Material Planning'!$D$9 -> 17 | E35: ='Cumulative Material Use'!$E$4 -> 0.2646 | H35: ='Cumulative Material Use'!$E$38 -> 0.0636 | K35: =E35*$K$5 -> 0 | L35: =F35*$L$5 -> 0 | M35: =G35*$M$5 -> 0 | N35: =H35*$N$5 -> 0 | O35: =I35*$O$5 -> 0 | P35: =SUM(K35:O35) -> 0 | R35: =P35-Q35 -> 0 | S35: =R35/D35 -> 0 | X35: =E35*$AD$5 -> 0 | Y35: =F35*$AE$5 -> 0 | Z35: =G35*$AF$5 -> 0 | AA35: =H35*$AG$5 -> 0 | AB35: =I35*$AH$5 -> 0 | AC35: =SUM(X35:AB35) -> 0 | AI35: =SUM(AD35:AH35) -> 0
B36: 10154 | C36: SS439; Sheet; With PVC Coating; 0.6mm thk x 1219mm W × 2438mm L | D36: ='Monthly Material Planning'!$D$10 -> 13.5 | E36: ='Cumulative Material Use'!$E$5 -> 0.054 | F36: ='Cumulative Material Use'!$E$13 -> 0.1646 | G36: ='Cumulative Material Use'!$E$20 -> 0.68471 | H36: ='Cumulative Material Use'!$E$35 -> 0.1899 | I36: ='Cumulative Material Use'!$E$31 -> 0.0576 | K36: =E36*$K$5 -> 0 | L36: =F36*$L$5 -> 0 | M36: =G36*$M$5 -> 0 | N36: =H36*$N$5 -> 0 | O36: =I36*$O$5 -> 0 | P36: =SUM(K36:O36) -> 0 | R36: =P36-Q36 -> 0 | S36: =R36/D36 -> 0 | X36: =E36*$AD$5 -> 0 | Y36: =F36*$AE$5 -> 0 | Z36: =G36*$AF$5 -> 0 | AA36: =H36*$AG$5 -> 0 | AB36: =I36*$AH$5 -> 0 | AC36: =SUM(X36:AB36) -> 0 | AI36: =SUM(AD36:AH36) -> 0
B37: 10155 | C37: SS439; Sheet; With PVC Coating; 0.8mm thk × 1219mm W x 2438mm L | D37: ='Monthly Material Planning'!$D$11 -> 18.1 | E37: ='Cumulative Material Use'!$E$6 -> 0.66821 | F37: ='Cumulative Material Use'!$E$15 -> 0.50701 | G37: ='Cumulative Material Use'!$E$26 -> 0.0789 | H37: ='Cumulative Material Use'!$E$36 -> 0.4622 | K37: =E37*$K$5 -> 0 | L37: =F37*$L$5 -> 0 | M37: =G37*$M$5 -> 0 | N37: =H37*$N$5 -> 0 | O37: =I37*$O$5 -> 0 | P37: =SUM(K37:O37) -> 0 | R37: =P37-Q37 -> 0 | S37: =R37/D37 -> 0 | X37: =E37*$AD$5 -> 0 | Y37: =F37*$AE$5 -> 0 | Z37: =G37*$AF$5 -> 0 | AA37: =H37*$AG$5 -> 0 | AB37: =I37*$AH$5 -> 0 | AC37: =SUM(X37:AB37) -> 0 | AI37: =SUM(AD37:AH37) -> 0
B38: 11332 | C38: SS321; Sheet; 1.5mm thk × 1000mm W x 2660mm L | D38: ='Monthly Material Planning'!$D$12 -> 31.7 | E38: ='Cumulative Material Use'!$E$7 -> 0.5167 | F38: ='Cumulative Material Use'!$E$16 -> 0.5267 | H38: ='Cumulative Material Use'!$E$42 -> 0.5852 | K38: =E38*$K$5 -> 0 | L38: =F38*$L$5 -> 0 | M38: =G38*$M$5 -> 0 | N38: =H38*$N$5 -> 0 | O38: =I38*$O$5 -> 0 | P38: =SUM(K38:O38) -> 0 | R38: =P38-Q38 -> 0 | S38: =R38/D38 -> 0 | X38: =E38*$AD$5 -> 0 | Y38: =F38*$AE$5 -> 0 | Z38: =G38*$AF$5 -> 0 | AA38: =H38*$AG$5 -> 0 | AB38: =I38*$AH$5 -> 0 | AC38: =SUM(X38:AB38) -> 0 | AI38: =SUM(AD38:AH38) -> 0
B39: 10070B | C39: 1008 0.6 CRCA Carbon Steel; Sheet; 1219mm W × 2675mm L | D39: ='Monthly Material Planning'!$D$13 -> 15.6 | E39: ='Cumulative Material Use'!$E$8 -> 1.08 | H39: ='Cumulative Material Use'!$E$39 -> 0.8213 | K39: =E39*$K$5 -> 0 | L39: =F39*$L$5 -> 0 | M39: =G39*$M$5 -> 0 | N39: =H39*$N$5 -> 0 | O39: =I39*$O$5 -> 0 | P39: =SUM(K39:O39) -> 0 | R39: =P39-Q39 -> 0 | S39: =R39/D39 -> 0 | X39: =E39*$AD$5 -> 0 | Y39: =F39*$AE$5 -> 0 | Z39: =G39*$AF$5 -> 0 | AA39: =H39*$AG$5 -> 0 | AB39: =I39*$AH$5 -> 0 | AC39: =SUM(X39:AB39) -> 0 | AI39: =SUM(AD39:AH39) -> 0
B40: 11090 | C40: SS201; Sheet; With PVC Coating; 0.5mm thk x 1219.2mm W × 2675mm L; Hairline | D40: ='Monthly Material Planning'!$D$14 -> 12.7 | E40: ='Cumulative Material Use'!$E$9 -> 0.0356 | F40: ='Cumulative Material Use'!$E$14 -> 0.07214 | G40: ='Cumulative Material Use'!$E$23 -> 0.01154 | H40: ='Cumulative Material Use'!$E$40 -> 0.01154 | I40: ='Cumulative Material Use'!$E$30 -> 0.40645 | K40: =E40*$K$5 -> 0 | L40: =F40*$L$5 -> 0 | M40: =G40*$M$5 -> 0 | N40: =H40*$N$5 -> 0 | O40: =I40*$O$5 -> 0 | P40: =SUM(K40:O40) -> 0 | R40: =P40-Q40 -> 0 | S40: =R40/D40 -> 0 | X40: =E40*$AD$5 -> 0 | Y40: =F40*$AE$5 -> 0 | Z40: =G40*$AF$5 -> 0 | AA40: =H40*$AG$5 -> 0 | AB40: =I40*$AH$5 -> 0 | AC40: =SUM(X40:AB40) -> 0 | AI40: =SUM(AD40:AH40) -> 0
B41: 10073 | C41: Carbon Steel Tubing; 10mm OD x 1mm wall x 3m L | D41: ='Monthly Material Planning'!$D$15 -> 0 | E41: ='Cumulative Material Use'!$E$10 -> 0.11 | H41: ='Cumulative Material Use'!$E$41 -> 0.11 | K41: =E41*$K$5 -> 0 | L41: =F41*$L$5 -> 0 | M41: =G41*$M$5 -> 0 | N41: =H41*$N$5 -> 0 | O41: =I41*$O$5 -> 0 | P41: =SUM(K41:O41) -> 0 | R41: =P41-Q41 -> 0 | S41: =R41/D41 -> #DIV/0! | X41: =E41*$AD$5 -> 0 | Y41: =F41*$AE$5 -> 0 | Z41: =G41*$AF$5 -> 0 | AA41: =H41*$AG$5 -> 0 | AB41: =I41*$AH$5 -> 0 | AC41: =SUM(X41:AB41) -> 0 | AI41: =SUM(AD41:AH41) -> 0
B42: 10970 | C42: AZ150 0.6mm Galvalume Coated Steel Sheet; 1219mm w x 2500mm L (DX53D) | D42: ='Monthly Material Planning'!$D$16 -> 13.6 | F42: ='Cumulative Material Use'!$E$12 -> 0.4103 | K42: =E42*$K$5 -> 0 | L42: =F42*$L$5 -> 0 | M42: =G42*$M$5 -> 0 | N42: =H42*$N$5 -> 0 | O42: =I42*$O$5 -> 0 | P42: =SUM(K42:O42) -> 0 | R42: =P42-Q42 -> 0 | S42: =R42/D42 -> 0 | X42: =E42*$AD$5 -> 0 | Y42: =F42*$AE$5 -> 0 | Z42: =G42*$AF$5 -> 0 | AA42: =H42*$AG$5 -> 0 | AB42: =I42*$AH$5 -> 0 | AC42: =SUM(X42:AB42) -> 0 | AI42: =SUM(AD42:AH42) -> 0
B43: 11213B | C43: SS201; Sheet; With PVC Coating; 0.4mm thk x 1219mm W × 2438mm L; Hairline | D43: ='Monthly Material Planning'!$D$17 -> 10 | F43: ='Cumulative Material Use'!$E$17 -> 0.55556 | K43: =E43*$K$5 -> 0 | L43: =F43*$L$5 -> 0 | M43: =G43*$M$5 -> 0 | N43: =H43*$N$5 -> 0 | O43: =I43*$O$5 -> 0 | P43: =SUM(K43:O43) -> 0 | R43: =P43-Q43 -> 0 | S43: =R43/D43 -> 0 | X43: =E43*$AD$5 -> 0 | Y43: =F43*$AE$5 -> 0 | Z43: =G43*$AF$5 -> 0 | AA43: =H43*$AG$5 -> 0 | AB43: =I43*$AH$5 -> 0 | AC43: =SUM(X43:AB43) -> 0 | AI43: =SUM(AD43:AH43) -> 0
...

Sheet Week 2
C3: RAW MATERIAL REQUISITION & RECEIPT FORM
C4: FACILITY: | D4: _____________________________
C5: DATE: | D5: _____________________________ | I5: Production Supervisor: | J5: _____________________________ | Q5: Production Supervisor: | R5: _____________________________
C6: WEEK NO.: | D6: _____________________________ | I6: Key Operator: | J6: _____________________________ | Q6: Key Operator: | R6: _____________________________
C8: Part No. | D8: Material Descritpion | E8: Weekly Quantity Requested (Kgs) | F8: Quantity Received
F9: Monday | H9: Tuesday | J9: Wednesday | L9: Thursday | N9: Friday | P9: Saturday | R9: Sunday | T9: Weekly Total Received (Kgs) | U9: Comments
F10: Qty Requested | G10: Qty Received | H10: Qty Requested | I10: Qty Received | J10: Qty Requested | K10: Qty Received | L10: Qty Requested | M10: Qty Received | N10: Qty Requested | O10: Qty Received | P10: Qty Requested | Q10: Qty Received | R10: Qty Requested | S10: Qty Received
C11: 11279 | D11: AZ150 0.6mm Galvalume Coated Carbon Steel; Sheet; 1219mm W × 2300mm L
C12: 10072B | D12: AZ100 0.7 Galvalume Sheet; 1219mm W x 2438mm L
C13: 10154 | D13: SS439; Sheet; With PVC Coating; 0.6mm thk x 1219mm W × 2438mm L
C14: 10155 | D14: SS439; Sheet; With PVC Coating; 0.8mm thk × 1219mm W x 2438mm L
C15: 11332 | D15: SS321; Sheet; 1.5mm thk × 1000mm W x 2660mm L
C16: 10070B | D16: 1008 0.6 CRCA Carbon Steel; Sheet; 1219mm W × 2675mm L
C17: 11090 | D17: SS201; Sheet; With PVC Coating; 0.5mm thk x 1219.2mm W × 2675mm L; Hairline
C18: 10073 | D18: Carbon Steel Tubing; 10mm OD x 1mm wall x 3m L
C19: 10970 | D19: AZ150 0.6mm Galvalume Coated Steel Sheet; 1219mm w x 2500mm L (DX53D)
C20: 11213B | D20: SS201; Sheet; With PVC Coating; 0.4mm thk x 1219mm W × 2438mm L; Hairline
C21: 11442 | D21: SS201; Sheet; Without PVC Coating; 0.8mm thk x 1219mm W × 2438mm L; BA Finish
C22: 11515 | D22: SS201; Sheet; With PVC Coating; 0.4mm thk x 1219mm × 2190mm L; Hairline
C23: 10296A | D23: AZ100 0.2 Galvalume Sheet; 975mm W x 2438mm L
C24: 11040B | D24: SS304; Sheet; 1.2mm thk × 1219.2mm W × 2620mm L
C25: 11226 | D25: SS439; Sheet; 1.2mm thk × 1219mm W × 2438mm L
C26: 10074 | D26: SS304; Sheet; 0.8mm x 1219mm W × 2438mm L
C27: 11291 | D27: SS201; Wire; 4mm dia x 2400mm L
C28: 11290 | D28: SS201; Wire; 3mm dia x 2400mm L
C29: Production Supervisor Sign Off:
C30: Warehouse Supervisor Sign Off:
D32: Remarks:
C33: MON: | D33: _________________________________________________________________________________________________________________________________________________________________________________________________________________________________________________________________________________________________________________________
C34: TUE: | D34: _________________________________________________________________________________________________________________________________________________________________________________________________________________________________________________________________________________________________________________________
C35: WED: | D35: _________________________________________________________________________________________________________________________________________________________________________________________________________________________________________________________________________________________________________________________
C36: THUR: | D36: _________________________________________________________________________________________________________________________________________________________________________________________________________________________________________________________________________________________________________________________
C37: FRI: | D37: _________________________________________________________________________________________________________________________________________________________________________________________________________________________________________________________________________________________________________________________
C38: SAT: | D38: _________________________________________________________________________________________________________________________________________________________________________________________________________________________________________________________________________________________________________________________
C39: SUN: | D39: _________________________________________________________________________________________________________________________________________________________________________________________________________________________________________________________________________________________________________________________
D41: Production Representative: | E41: ____________________________________________________ | L41: Date: | M41: ______________________________ | S41: Sign: | T41: ______________________________
D42: Warehouse Representative: | E42: ____________________________________________________ | L42: Date: | M42: ______________________________ | S42: Sign: | T42: ______________________________
D43: Production Manager: | E43: ____________________________________________________ | L43: Date: | M43: ______________________________ | S43: Sign: | T43: ______________________________

Sheet Cumulative Material Use
B2: Product | C2: Raw Material Description | D2: Material Part # | E2: Utilization/ Stove (NAV) | F2: Utilization/ Stove (Calculated) | G2: Variance [NAV vs Calc] | H2: Theoretical Scrap %
B3: KCB2 | C3: AZ150 0.6mm Galvalume Coated Carbon Steel; Sheet; 1219mm W × 2300mm L | D3: 11279 | E3: =(Table1[[#This Row],[Utilization/ pc in NAV (Kg)]]*Table1[[#This Row],[Qnty/ Stove]])+('Master Data'!E4*'Master Data'!F4)+('Master Data'!E5*'Master Data'!F5)+('Master Data'!E15*'Master Data'!F15) -> 0.9643 | F3: =(Table1[[#This Row],[Qnty/ Stove]]*Table1[[#This Row],[Calculated Utilization (Kg)]])+('Master Data'!F4*'Master Data'!M4)+('Master Data'!F5*'Master Data'!M5)+('Master Data'!F15*'Master Data'!M15) -> 0.9349298 | G3: =F3-E3 -> -0.029370203
C4: AZ100 0.7 Galvalume Sheet; 1219mm W x 2438mm L | D4: 10072B | E4: =('Master Data'!E6*'Master Data'!F6)+('Master Data'!E16*'Master Data'!F16) -> 0.2646 | F4: =('Master Data'!F6*'Master Data'!M6)+('Master Data'!F16*'Master Data'!M16) -> 0.27996032 | G4: =F4-E4 -> 0.015360317
C5: SS439; Sheet; With PVC Coating; 0.6mm thk x 1219mm W × 2438mm L | D5: 10154 | E5: ='Master Data'!E7*'Master Data'!F7 -> 0.054 | F5: =('Master Data'!F7*'Master Data'!M7) -> 0.060267857 | G5: =F5-E5 -> 0.0062678571
C6: SS439; Sheet; With PVC Coating; 0.8mm thk × 1219mm W x 2438mm L | D6: 10155 | E6: =('Master Data'!E8*'Master Data'!F8)+('Master Data'!E9*'Master Data'!F9)+('Master Data'!E10*'Master Data'!F10)+('Master Data'!E12*'Master Data'!F12)+('Master Data'!E13*'Master Data'!F13)+('Master Data'!E14*'Master Data'!F14) -> 0.66821 | F6: =('Master Data'!F8*'Master Data'!M8)+('Master Data'!F9*'Master Data'!M9)+('Master Data'!F10*'Master Data'!M10)+('Master Data'!F12*'Master Data'!M12)+('Master Data'!F13*'Master Data'!M13)+('Master Data'!F14*'Master Data'!M14) -> 0.71627091 | G6: =F6-E6 -> 0.04806091
C7: SS321; Sheet; 1.5mm thk × 1000mm W x 2660mm L | D7: 11332 | E7: ='Master Data'!E11*'Master Data'!F11 -> 0.5167 | F7: ='Master Data'!F11*'Master Data'!M11 -> 0.52833333 | G7: =F7-E7 -> 0.011633333
C8: 1008 0.6 CRCA Carbon Steel; Sheet; 1219mm W × 2675mm L | D8: 10070B | E8: ='Master Data'!E18*'Master Data'!F18 -> 1.08 | F8: ='Master Data'!F18*'Master Data'!M18 -> 1.1142857 | G8: =F8-E8 -> 0.034285714
C9: SS201; Sheet; With PVC Coating; 0.5mm thk x 1219.2mm W × 2675mm L; Hairline | D9: 11090 | E9: ='Master Data'!E19*'Master Data'!F19 -> 0.0356 | F9: =('Master Data'!F19*'Master Data'!M19)+('Master Data'!F20*'Master Data'!M20) -> 0.04825524 | G9: =F9-E9 -> 0.01265524
C10: Carbon Steel Tubing; 10mm OD x 1mm wall x 3m L | D10: 10073 | E10: ='Master Data'!E17*'Master Data'!F17 -> 0.11
B11: KCA5 | C11: AZ150 0.6mm Galvalume Coated Carbon Steel; Sheet; 1219mm W × 2300mm L | D11: 11279 | E11: =('Master Data'!E21*'Master Data'!F21)+('Master Data'!E23*'Master Data'!F23) -> 0.2414 | F11: =('Master Data'!F21*'Master Data'!M21)+('Master Data'!F23*'Master Data'!M23) -> 0.2359596 | G11: =F11-E11 -> -0.005440404
C12: AZ150 0.6mm Galvalume Coated Steel Sheet; 1219mm w x 2500mm L (DX53D) | D12: 10970 | E12: =('Master Data'!E22*'Master Data'!F22)+('Master Data'!E33*'Master Data'!F33)+('Master Data'!E34*'Master Data'!F34) -> 0.4103 | F12: =('Master Data'!F22*'Master Data'!M22)+('Master Data'!F33*'Master Data'!M33)+('Master Data'!F34*'Master Data'!M34) -> 0.38857143 | G12: =F12-E12 -> -0.021728571
C13: SS439; Sheet; With PVC Coating; 0.6mm thk x 1219mm W × 2438mm L | D13: 10154 | E13: ='Master Data'!E24*'Master Data'!F24 -> 0.1646 | F13: ='Master Data'!F24*'Master Data'!M24 -> 0.16875 | G13: =F13-E13 -> 0.00415
C14: SS201; Sheet; With PVC Coating; 0.5mm thk x 1219.2mm W × 2675mm L; Hairline | D14: 11090 | E14: =('Master Data'!E25*'Master Data'!F25)+('Master Data'!E26*'Master Data'!F26)+('Master Data'!E37*'Master Data'!F37) -> 0.07214 | F14: =('Master Data'!F25*'Master Data'!M25)+('Master Data'!F26*'Master Data'!M26)+('Master Data'!F37*'Master Data'!M37) -> 0.064598219 | G14: =F14-E14 -> -0.0075417806
C15: SS439; Sheet; With PVC Coating; 0.8mm thk × 1219mm | D15: 10155 | E15: =('Master Data'!E27*'Master Data'!F27)+('Master Data'!E29*'Master Data'!F29)+('Master Data'!E30*'Master Data'!F30)+('Master Data'!E31*'Master Data'!F31)+('Master Data'!E32*'Master Data'!F32) -> 0.50701 | F15: =('Master Data'!F27*'Master Data'!M27)+('Master Data'!F29*'Master Data'!M29)+('Master Data'!F30*'Master Data'!M30)+('Master Data'!F31*'Master Data'!M30)+('Master Data'!F31*'Master Data'!M31)+('Master Data'!F32*'Master Data'!M32) -> 0.54200239 | G15: =F15-E15 -> 0.034992388
C16: SS321; Sheet; 1.5mm thk × 1000mm W x 2660mm L | D16: 11332 | E16: ='Master Data'!E28*'Master Data'!F28 -> 0.5267 | F16: ='Master Data'!F28*'Master Data'!M28 -> 0.52833333 | G16: =F16-E16 -> 0.0016333333
C17: SS201; Sheet; With PVC Coating; 0.4mm thk x 1219mm W × 2438mm L; Hairline | D17: 11213B | E17: ='Master Data'!E35*'Master Data'!F35 -> 0.55556 | F17: ='Master Data'!F35*'Master Data'!M35 -> 0.55555556 | G17: =F17-E17 -> -4.4444444e-06
C18: SS201; Sheet; Without PVC Coating; 0.8mm thk x 1219mm W × 2438mm L; BA Finish | D18: 11442 | E18: ='Master Data'!E36*'Master Data'!F36 -> 0.07434 | F18: ='Master Data'!F36*'Master Data'!M36 -> 0.075641026 | G18: =F18-E18 -> 0.0013010256
B19: KWB3.1 | C19: SS201; Sheet; With PVC Coating; 0.4mm thk x 1219mm × 2190mm L; Hairline | D19: 11515 | E19: =('Master Data'!E38*'Master Data'!F38)+('Master Data'!E46*'Master Data'!F46) -> 0.71703
C20: SS439; Sheet; With PVC Coating; 0.6mm thk x 1219mm W × 2438mm L | D20: 10154 | E20: =('Master Data'!E39*'Master Data'!F39)+('Master Data'!E47*'Master Data'!F47)+('Master Data'!E51*'Master Data'!F51)+('Master Data'!E52*'Master Data'!F52)+('Master Data'!E54*'Master Data'!F54)+('Master Data'!E55*'Master Data'!F55)+('Master Data'!E56*'Master Data'!F56) -> 0.68471 | F20: =('Master Data'!F39*'Master Data'!M39)+('Master Data'!F47*'Master Data'!M47)+('Master Data'!F51*'Master Data'!M51)+('Master Data'!F52*'Master Data'!M52)+('Master Data'!F54*'Master Data'!M54)+('Master Data'!F55*'Master Data'!M55)+('Master Data'!F56*'Master Data'!M56) -> 0.67259477 | G20: =F20-E20 -> -0.012115228
C21: SS201; Sheet; Without PVC Coating; 0.8mm thk x 1219mm W × 2438mm L; BA Finish | D21: 11442 | E21: ='Master Data'!E40*'Master Data'!F40 -> 0.07434 | F21: ='Master Data'!F40*'Master Data'!M40 -> 0.075641026 | G21: =F21-E21 -> 0.0013010256
C22: AZ100 0.2 Galvalume Sheet; 975mm W x 2438mm L | D22: 10296A | E22: ='Master Data'!E41*'Master Data'!F41 -> 0.1961 | F22: ='Master Data'!F41*'Master Data'!M41 -> 0.19722222 | G22: =F22-E22 -> 0.0011222222
C23: SS201; Sheet; With PVC Coating; 0.5mm thk x 1219.2mm W × 2675mm L; Hairline | D23: 11090 | E23: ='Master Data'!E42*'Master Data'!F42 -> 0.01154 | F23: ='Master Data'!F42*'Master Data'!M42 -> 0.011229001 | G23: =F23-E23 -> -0.00031099912
C24: AZ150 0.6mm Galvalume Coated Carbon Steel; Sheet; 1219mm W × 2300mm L | D24: 11279 | E24: =('Master Data'!E43*'Master Data'!F43)+('Master Data'!E44*'Master Data'!F44)+('Master Data'!E45*'Master Data'!F45) -> 0.5068
C25: SS304; Sheet; 1.2mm thk × 1219.2mm W × 2620mm L | D25: 11040B | E25: ='Master Data'!E48*'Master Data'!F48 -> 0.4495 | F25: ='Master Data'!F48*'Master Data'!M48 -> 0.45151515 | G25: =F25-E25 -> 0.0020151515
C26: SS439; Sheet; With PVC Coating; 0.8mm thk × 1219mmW x 2438mm L | D26: 10155 | E26: ='Master Data'!E49*'Master Data'!F49 -> 0.0789 | F26: ='Master Data'!F49*'Master Data'!M49 -> 0.078695652 | G26: =F26-E26 -> -0.00020434783
C27: SS439; Sheet; 1.2mm thk × 1219mm W × 2438mm L | D27: 11226 | E27: =('Master Data'!E50*'Master Data'!F50)+('Master Data'!E53*'Master Data'!F53) -> 0.47901 | F27: =('Master Data'!F50*'Master Data'!M50)+('Master Data'!F53*'Master Data'!M53) -> 0.48479167 | G27: =F27-E27 -> 0.0057816667
C28: SS201; Wire; 4mm dia x 2400mm L | D28: 11291 | E28: ='Master Data'!E57*'Master Data'!F57 -> 0.0804
C29: SS201; Wire; 3mm dia x 2400mm L | D29: 11290 | E29: ='Master Data'!E58*'Master Data'!F58 -> 0.0555
B30: KAB3 | C30: SS201; Sheet; With PVC Coating; 0.5mm thk x 1219.2mm W × 2675mm L; Hairline | D30: 11090 | E30: ='Master Data'!E59*'Master Data'!F59 -> 0.40645 | F30: ='Master Data'!F59*'Master Data'!M59 -> 0.40967742 | G30: =F30-E30 -> 0.0032274194
C31: SS439; Sheet; With PVC Coating; 0.6mm thk x 1219mm W × 2438mm L | D31: 10154 | E31: ='Master Data'!E60*'Master Data'!F60 -> 0.0576 | F31: ='Master Data'!F60*'Master Data'!M60 -> 0.054788961 | G31: =F31-E31 -> -0.002811039
C32: SS304; Sheet; 1.2mm thk × 1219.2mm W × 2620mm L | D32: 11040B | E32: =('Master Data'!E61*'Master Data'!F61)+('Master Data'!E62*'Master Data'!F62)+('Master Data'!E64*'Master Data'!F64) -> 0.0266 | F32: =('Master Data'!F61*'Master Data'!M61)+('Master Data'!F62*'Master Data'!M62)+('Master Data'!F64*'Master Data'!M64) -> 0.025120812 | G32: =F32-E32 -> -0.0014791879
C33: SS439; Sheet; 1.2mm thk × 1219mm W × 2438mm L | D33: 11226 | E33: ='Master Data'!E63*'Master Data'!F63 -> 0 | F33: ='Master Data'!F63*'Master Data'!M63 -> 0 | G33: =F33-E33 -> 0
B34: KCA3.5 SOM | C34: AZ150 0.6mm Galvalume Coated Carbon Steel; Sheet; 1219mm W × 2300mm L | D34: 11279 | E34: =('Master Data'!F65*'Master Data'!L65)+('Master Data'!F66*'Master Data'!L66)+('Master Data'!F67*'Master Data'!L67)+('Master Data'!F68*'Master Data'!L68)+('Master Data'!F69*'Master Data'!L69)+('Master Data'!F76*'Master Data'!L76)+('Master Data'!F84*'Master Data'!L84) -> 0.969
C35: SS439; Sheet; With PVC Coating; 0.6mm thk x 1219mm W × 2438mm L | D35: 10154 | E35: =('Master Data'!F70*'Master Data'!L70)+('Master Data'!F74*'Master Data'!L74)+('Master Data'!F81*'Master Data'!L81) -> 0.1899
C36: SS439; Sheet; With PVC Coating; 0.8mm thk × 1219mmW x 2438mm L | D36: 10155 | E36: =('Master Data'!F71*'Master Data'!L71)+('Master Data'!F72*'Master Data'!L72)+('Master Data'!F73*'Master Data'!L73) -> 0.4622
C37: SS304; Sheet; 0.8mm x 1219mm W × 2438mm L | D37: 10074 | E37: ='Master Data'!F75*'Master Data'!L75 -> 0.00792
C38: AZ100 0.7 Galvalume Sheet; 1219mm W x 2438mm L | D38: 10072B | E38: ='Master Data'!F77*'Master Data'!L77 -> 0.0636
C39: 1009 0.6 CRCA Carbon Steel; Sheet; 1219mm W × 2675mm L | D39: 10070B | E39: =('Master Data'!F78*'Master Data'!L78)+('Master Data'!F79*'Master Data'!L79)+('Master Data'!F80*'Master Data'!L80) -> 0.8213
C40: SS201; Sheet; With PVC Coating; 0.5mm thk x 1219.2mm W × 2675mm L; Hairline | D40: 11090 | E40: ='Master Data'!F82*'Master Data'!L82 -> 0.01154
C41: Carbon Steel Tubing; 10mm OD x 1mm wall x 3m L | D41: 10073 | E41: ='Master Data'!F83*'Master Data'!L83 -> 0.11
...

Sheet Master Data
B2: Component/Part | C2: Material Description | D2: Material Number | E2: Utilization/ pc in NAV (Kg) | F2: Qnty/ Stove | G2: Shear Plan Available? | H2: Nesting Plan Available? | I2: Material match - BOM vs Shear/ Nest Plan | J2: Sheet Weight (Kg) | K2: Parts/ Sheet | L2: Current BOM Utilization (Kg) | M2: Calculated Utilization (Kg) | N2: Variance (Kg) | O2: Sheet Wt Used in BOM Calc (Kg) | P2: Actual Part Wt (Kg) | Q2: Expected Scrap per Part (Kg) | R2: Expected Scrap per Stove (Kg)2 | S2: % Factored Scrap | T2: Av % scrap/ Product | U2: Remarks | V2: Column1
B3: Bridge; Flat With Holes; KCA4 | C3: AZ150 0.6mm Galvalume Coated Carbon Steel; Sheet; 1219mm W × 2300mm L | D3: 11279 | E3: 0.2045 | F3: 1 | G3: Y | I3: N - 2438L vs 2300L in BOM, no effect on # of parts | J3: 12.8 | K3: 56 | L3: 0.2045 | M3: =(J3-(M5*6))/K3 -> 0.2031746 | N3: =IFERROR(M3-L3, "") -> -0.0013253968 | P3: 0.1543 | Q3: =Table1[[#This Row],[Current BOM Utilization (Kg)]]-P3 -> 0.0502 | S3: =IFERROR((Table1[[#This Row],[Calculated Utilization (Kg)]]-Table1[[#This Row],[Actual Part Wt (Kg)]])/Table1[[#This Row],[Calculated Utilization (Kg)]], "") -> 0.24055469 | U3: Shear plan needs revision, offcut from 2438L can make 3 Bottoms, 2300L can't but can do KCA4 False Bottom | V3: Needs an official shear Plan
B4: Bridge Hat; Flat Laser-cut; KCB2 | C4: AZ150 0.6mm Galvalume Coated Carbon Steel; Sheet; 1219mm W × 2300mm L | D4: 11279 | E4: 0.0527 | F4: 1 | H4: Y | I4: Y | J4: 12.8 | K4: 264 | L4: 0.0527 | M4: =J4/K4 -> 0.048484848 | N4: =IFERROR(M4-L4, "") -> -0.0042151515 | P4: 0.0319 | Q4: =Table1[[#This Row],[Current BOM Utilization (Kg)]]-P4 -> 0.0208 | S4: =IFERROR((Table1[[#This Row],[Calculated Utilization (Kg)]]-Table1[[#This Row],[Actual Part Wt (Kg)]])/Table1[[#This Row],[Calculated Utilization (Kg)]], "") -> 0.3420625
B5: False Bottom; Fully formed; KCA4 | C5: AZ150 0.6mm Galvalume Coated Carbon Steel; Sheet; 1219mm W × 2300mm L | D5: 11279 | E5: 0.225 | F5: 1 | G5: Y | I5: N - 2438L vs 2300L in BOM, no effect on # of parts | J5: 12.8 | K5: 54 | L5: 0.225 | M5: =J5/K5 -> 0.23703704 | N5: =IFERROR(M5-L5, "") -> 0.012037037 | P5: 0.148 | Q5: =Table1[[#This Row],[Current BOM Utilization (Kg)]]-P5 -> 0.077 | S5: =IFERROR((Table1[[#This Row],[Calculated Utilization (Kg)]]-Table1[[#This Row],[Actual Part Wt (Kg)]])/Table1[[#This Row],[Calculated Utilization (Kg)]], "") -> 0.375625 | V5: Needs an official shear Plan
B6: Ash Tray; Formed; KCA4 | C6: AZ100 0.7 Galvalume Sheet; 1219mm W x 2438mm L | D6: 10072B | E6: 0.201 | F6: 1 | H6: Y | I6: Y | J6: 17 | K6: 80 | L6: 0.201 | M6: =J6/K6 -> 0.2125 | N6: =IFERROR(M6-L6, "") -> 0.0115 | P6: 0.1795 | Q6: =Table1[[#This Row],[Current BOM Utilization (Kg)]]-P6 -> 0.0215 | S6: =IFERROR((Table1[[#This Row],[Calculated Utilization (Kg)]]-Table1[[#This Row],[Actual Part Wt (Kg)]])/Table1[[#This Row],[Calculated Utilization (Kg)]], "") -> 0.15529412
B7: Door; Formed With Emboss; KCA4 | C7: SS439; Sheet; With PVC Coating; 0.6mm thk x 1219mm W × 2438mm L | D7: 10154 | E7: 0.054 | F7: 1 | G7: N | J7: 13.5 | K7: 224 | L7: 0.054 | M7: =J7/K7 -> 0.060267857 | N7: =IFERROR(M7-L7, "") -> 0.0062678571 | O7: 13.5 | P7: 0.0468 | Q7: =Table1[[#This Row],[Current BOM Utilization (Kg)]]-P7 -> 0.0072 | S7: =IFERROR((Table1[[#This Row],[Calculated Utilization (Kg)]]-Table1[[#This Row],[Actual Part Wt (Kg)]])/Table1[[#This Row],[Calculated Utilization (Kg)]], "") -> 0.22346667 | U7: Needs a new shear plan | V7: Needs an official shear Plan
B8: Ash Tray Handle Strip; Flat; KCA2 | C8: SS439; Sheet; With PVC Coating; 0.8mm thk × 1219mm W x 2438mm L | D8: 10155 | E8: 0.0117 | F8: 1 | G8: Y | I8: Y | J8: 18.1 | K8: 1701 | L8: 0.0117 | M8: =J8/K8 -> 0.0106408 | N8: =IFERROR(M8-L8, "") -> -0.0010592005 | P8: 0.015 | Q8: =Table1[[#This Row],[Current BOM Utilization (Kg)]]-P8 -> -0.0033 | S8: =IFERROR((Table1[[#This Row],[Calculated Utilization (Kg)]]-Table1[[#This Row],[Actual Part Wt (Kg)]])/Table1[[#This Row],[Calculated Utilization (Kg)]], "") -> -0.40966851 | U8: Confirm the # in the shear plan is attainable, if not update number specified on the shear plan
B9: Cone Deck; Formed; KCB2 | C9: SS439; Sheet; With PVC Coating; 0.8mm thk × 1219mmW x 2438mm L | D9: 10155 | E9: 0.3872 | F9: 1 | H9: Y | I9: Y | J9: 18.1 | K9: 27 | L9: 0.3872 | M9: =(J9-((M10*135)+(M12*27)))/K9 -> 0.38507966 | N9: =IFERROR(M9-L9, "") -> -0.0021203433 | P9: 0.2905 | Q9: =Table1[[#This Row],[Current BOM Utilization (Kg)]]-P9 -> 0.0967 | S9: =IFERROR((Table1[[#This Row],[Calculated Utilization (Kg)]]-Table1[[#This Row],[Actual Part Wt (Kg)]])/Table1[[#This Row],[Calculated Utilization (Kg)]], "") -> 0.24561063 | U9: Request for a full nest of Heat Shields & Pot Supports & determine how many we'd get, subtract to determine CD usage | V9: Done
B10: Pot Support; KCB2 | C10: SS439; Sheet; With PVC Coating; 0.8mm thk × 1219mmW x 2438mm L | D10: 10155 | E10: 0.01736 | F10: 5 | H10: Y | I10: Y | J10: 18.1 | K10: 955 | L10: 0.01736 | M10: =J10/K10 -> 0.01895288 | N10: =IFERROR(M10-L10, "") -> 0.0015928796 | P10: 0.015 | Q10: =Table1[[#This Row],[Current BOM Utilization (Kg)]]-P10 -> 0.00236 | S10: =IFERROR((Table1[[#This Row],[Calculated Utilization (Kg)]]-Table1[[#This Row],[Actual Part Wt (Kg)]])/Table1[[#This Row],[Calculated Utilization (Kg)]], "") -> 0.20856354 | U10: Get a full PS nest | V10: Done
B11: Combustion Chamber; Formed ; KCB2 | C11: SS321; Sheet; 1.5mm thk × 1000mm W x 2660mm L | D11: 11332 | E11: 0.5167 | F11: 1 | G11: N | H11: N | J11: 31.7 | K11: =6*10 -> 60 | L11: 0.5167 | M11: =J11/K11 -> 0.52833333 | N11: =IFERROR(M11-L11, "") -> 0.011633333 | O11: 31 | P11: =P28 -> 0.472 | Q11: =Table1[[#This Row],[Current BOM Utilization (Kg)]]-P11 -> 0.0447 | S11: =IFERROR((Table1[[#This Row],[Calculated Utilization (Kg)]]-Table1[[#This Row],[Actual Part Wt (Kg)]])/Table1[[#This Row],[Calculated Utilization (Kg)]], "") -> 0.10662461 | U11: No shear plan in Master Data, request for one, also confirm if it's possible to get a pdf laser nest for this
B12: Heat Shield; Flanged With Holes ; KCA5 | C12: SS439; Sheet; With PVC Coating; 0.8mm thk × 1219mmW x 2438mm L | D12: 10155 | E12: 0.1473 | F12: 1 | H12: Y | I12: Y | J12: 18.1 | K12: 95 | L12: 0.1473 | M12: =J12/K12 -> 0.19052632 | N12: =IFERROR(M12-L12, "") -> 0.043226316 | P12: =P29 -> 0.126 | Q12: =Table1[[#This Row],[Current BOM Utilization (Kg)]]-P12 -> 0.0213 | S12: =IFERROR((Table1[[#This Row],[Calculated Utilization (Kg)]]-Table1[[#This Row],[Actual Part Wt (Kg)]])/Table1[[#This Row],[Calculated Utilization (Kg)]], "") -> 0.33867403 | U12: Get a full HS nest
B13: Heat Shield Tab 1; Blank; KCA5 | C13: SS439; Sheet; With PVC Coating; 0.8mm thk × 1219mmW x 2438mm L | D13: 10155 | E13: 0.0109 | F13: 2 | H13: Y | J13: 18.1 | K13: 1540 | L13: 0.0109 | M13: =J13/K13 -> 0.011753247 | N13: =IFERROR(M13-L13, "") -> 0.00085324675 | P13: =P30 -> 0.008 | Q13: =Table1[[#This Row],[Current BOM Utilization (Kg)]]-P13 -> 0.0029 | S13: =IFERROR((Table1[[#This Row],[Calculated Utilization (Kg)]]-Table1[[#This Row],[Actual Part Wt (Kg)]])/Table1[[#This Row],[Calculated Utilization (Kg)]], "") -> 0.31933702 | U13: Request a full nest, parts from MMJ CD nest not sufficient. Do a review of MMJ CD nest - naming inter-changed, can we add more on the nest to support MMX?
B14: Heat Shield Tab 2; Flat; KCA5 | C14: SS439; Sheet; With PVC Coating; 0.8mm thk × 1219mmW x 2438mm L | D14: 10155 | E14: 0.01341 | F14: 1 | H14: Y | J14: 18.1 | K14: 1540 | L14: 0.01341 | M14: =J14/K14 -> 0.011753247 | N14: =IFERROR(M14-L14, "") -> -0.0016567532 | P14: =P31 -> 0.007 | Q14: =Table1[[#This Row],[Current BOM Utilization (Kg)]]-P14 -> 0.00641 | S14: =IFERROR((Table1[[#This Row],[Calculated Utilization (Kg)]]-Table1[[#This Row],[Actual Part Wt (Kg)]])/Table1[[#This Row],[Calculated Utilization (Kg)]], "") -> 0.40441989 | U14: Request a full nest, parts from MMJ CD nest not sufficient. Do a review of MMJ CD nest - naming inter-changed, can we add more on the nest to support MMX?
B15: Bottom; Formed; KCA4 | C15: AZ150 0.6mm Galvalume Coated Carbon Steel; Sheet; 1219mm W × 2300mm L | D15: 11279 | E15: 0.4821 | F15: 1 | G15: Y | I15: N | J15: 12.8 | K15: 21 | L15: 0.4821 | M15: =(J15-((M16*26)+(M5*12)))/K15 -> 0.44623331 | N15: =IFERROR(M15-L15, "") -> -0.035866692 | P15: 0.306 | Q15: =Table1[[#This Row],[Current BOM Utilization (Kg)]]-P15 -> 0.1761 | S15: =IFERROR((Table1[[#This Row],[Calculated Utilization (Kg)]]-Table1[[#This Row],[Actual Part Wt (Kg)]])/Table1[[#This Row],[Calculated Utilization (Kg)]], "") -> 0.31426006 | U15: Shear plan for the right sheet
B16: Foot; Formed; KCA4 | C16: AZ100 0.7 Galvalume Sheet; 1219mm W x 2438mm L | D16: 10072B | E16: 0.0212 | F16: 3 | G16: N | J16: 17 | K16: 756 | L16: 0.0212 | M16: =J16/K16 -> 0.022486772 | N16: =IFERROR(M16-L16, "") -> 0.0012867725 | O16: 16.05 | P16: 0.01652 | Q16: =Table1[[#This Row],[Current BOM Utilization (Kg)]]-P16 -> 0.00468 | S16: =IFERROR((Table1[[#This Row],[Calculated Utilization (Kg)]]-Table1[[#This Row],[Actual Part Wt (Kg)]])/Table1[[#This Row],[Calculated Utilization (Kg)]], "") -> 0.26534588 | U16: Do a new shear plan for KCA4 Foot | V16: Needs an official shear Plan
B17: SB Handle unformed; 10mm OD MS Tube; KCA2 | C17: Carbon Steel Tubing; 10mm OD x 1mm wall x 3m L | D17: 10073 | E17: 0.055 | F17: 2 | G17: N/A | J17: TBD | K17: 12 | L17: 0.055 | M17: TBD | N17: =IFERROR(M17-L17, "") | Q17: =Table1[[#This Row],[Current BOM Utilization (Kg)]]-P17 -> 0.055 | S17: =IFERROR((Table1[[#This Row],[Calculated Utilization (Kg)]]-Table1[[#This Row],[Actual Part Wt (Kg)]])/Table1[[#This Row],[Calculated Utilization (Kg)]], "") | V17: Needs an official shear Plan
B18: Side Body; punched; ECOA; un-coated; KCB2 | C18: 1008 0.6 CRCA Carbon Steel; Sheet; 1219mm W × 2675mm L | D18: 10070B | E18: 1.08 | F18: 1 | G18: Y | I18: Y | J18: 15.6 | K18: 14 | L18: 1.08 | M18: =J18/K18 -> 1.1142857 | N18: =IFERROR(M18-L18, "") -> 0.034285714 | P18: 0.889 | Q18: =Table1[[#This Row],[Current BOM Utilization (Kg)]]-P18 -> 0.191 | S18: =IFERROR((Table1[[#This Row],[Calculated Utilization (Kg)]]-Table1[[#This Row],[Actual Part Wt (Kg)]])/Table1[[#This Row],[Calculated Utilization (Kg)]], "") -> 0.20217949
B19: Logo Backing Plate; 52.0mm W × 171.9mm L; KCA5 | C19: SS201; Sheet; With PVC Coating; 0.5mm thk x 1219.2mm W × 2675mm L; Hairline | D19: 11090 | E19: 0.0356 | F19: 1 | H19: Y | I19: Y | J19: 12.7 | K19: 343 | L19: 0.0356 | M19: =J19/K19 -> 0.037026239 | N19: =IFERROR(M19-L19, "") -> 0.0014262391 | P19: 0.0322 | Q19: =Table1[[#This Row],[Current BOM Utilization (Kg)]]-P19 -> 0.0034 | S19: =IFERROR((Table1[[#This Row],[Calculated Utilization (Kg)]]-Table1[[#This Row],[Actual Part Wt (Kg)]])/Table1[[#This Row],[Calculated Utilization (Kg)]], "") -> 0.13034646
B20: Serialized Logo; Laser Marked; KCB2 | C20: SS201; Sheet; With PVC Coating; 0.5mm thk x 1219.2mm W × 2675mm L; Hairline | D20: 11090 | E20: 0.01154 | F20: 1 | G20: Y | H20: Y | I20: N | J20: 12.7 | K20: 1131 | L20: 0.01154 | M20: =J20/K20 -> 0.011229001 | N20: =IFERROR(M20-L20, "") -> -0.00031099912 | P20: =P37 -> 0.0096 | Q20: =Table1[[#This Row],[Current BOM Utilization (Kg)]]-P20 -> 0.00194 | R20: =SUM(Q3:Q20) -> 0.77989 | S20: =IFERROR((Table1[[#This Row],[Calculated Utilization (Kg)]]-Table1[[#This Row],[Actual Part Wt (Kg)]])/Table1[[#This Row],[Calculated Utilization (Kg)]], "") -> 0.14507087 | T20: =AVERAGE(S3:S19) -> 0.2164185 | U20: Shear plan outdated, needs to be updated
B21: Bridge Wall; Flat With formed rails; KCA5 | C21: AZ150 0.6mm Galvalume Coated Carbon Steel; Sheet; 1219mm W × 2300mm L | D21: 11279 | E21: 0.1116 | F21: 1 | H21: Y | I21: Y | J21: 12.8 | K21: 120 | L21: 0.1116 | M21: =J21/K21 -> 0.10666667 | N21: =IFERROR(M21-L21, "") -> -0.0049333333 | O21: 13.5 | P21: 0.093 | Q21: =Table1[[#This Row],[Current BOM Utilization (Kg)]]-P21 -> 0.0186 | S21: =IFERROR((Table1[[#This Row],[Calculated Utilization (Kg)]]-Table1[[#This Row],[Actual Part Wt (Kg)]])/Table1[[#This Row],[Calculated Utilization (Kg)]], "") -> 0.128125
B22: Bridge Hat; Flat with holes; KCA5 | C22: AZ150 0.6mm Galvalume Coated Steel Sheet; 1219mm w x 2500mm L (DX53D) | D22: 10970 | E22: 0.02 | F22: 1 | H22: Y | I22: Y | J22: 13.6 | K22: 731 | L22: 0.02 | M22: =J22/K22 -> 0.018604651 | N22: =IFERROR(M22-L22, "") -> -0.0013953488 | O22: 13.84 | P22: 0.016 | Q22: =Table1[[#This Row],[Current BOM Utilization (Kg)]]-P22 -> 0.004 | S22: =IFERROR((Table1[[#This Row],[Calculated Utilization (Kg)]]-Table1[[#This Row],[Actual Part Wt (Kg)]])/Table1[[#This Row],[Calculated Utilization (Kg)]], "") -> 0.14
B23: Bridge Base; Fully formed with holes; KCA5 | C23: AZ150 0.6mm Galvalume Coated Carbon Steel; Sheet; 1219mm W × 2300mm L | D23: 11279 | E23: 0.1298 | F23: 1 | G23: Y | I23: Y | J23: 12.8 | K23: 99 | L23: 0.1298 | M23: =J23/K23 -> 0.12929293 | N23: =IFERROR(M23-L23, "") -> -0.00050707071 | O23: 13.5 | P23: 0.091 | Q23: =Table1[[#This Row],[Current BOM Utilization (Kg)]]-P23 -> 0.0388 | S23: =IFERROR((Table1[[#This Row],[Calculated Utilization (Kg)]]-Table1[[#This Row],[Actual Part Wt (Kg)]])/Table1[[#This Row],[Calculated Utilization (Kg)]], "") -> 0.29617188 | U23: Material part # on shear plan needs updating
